<?xml version="1.0" encoding="utf-8"?>
<!-- This URDF was automatically created by SolidWorks to URDF Exporter! Originally created by Stephen Brawner (brawner@gmail.com) 
     Commit Version: 1.6.0-4-g7f85cfe  Build Version: 1.6.7995.38578
     For more information, please see http://wiki.ros.org/sw_urdf_exporter -->
<robot
  name="Smarticle_v3">
  <link
    name="base_linkv2">
    <contact>
        <lateral_friction value="0.15"/>
        <angular_friction value="0.3"/>
    </contact>
    <inertial>
      <origin
        xyz="-1.4344E-18 0.0004 0.00042795"
        rpy="0 0 0" />
      <mass
        value="0.0011628" />
      <inertia
        ixx="6.6584E-07"
        ixy="-6.5952E-26"
        ixz="-5.8585E-23"
        iyy="7.0794E-07"
        iyz="-2.635E-25"
        izz="4.2217E-08" />
    </inertial>
    <visual>
      <origin
        xyz="0 0 0"
        rpy="0 0 0" />
      <geometry>
        <mesh
          filename="../meshes/base_linkv2.STL" />
      </geometry>
      <material
        name="">
        <color
          rgba="0.79216 0.81961 0.93333 1" />
      </material>
    </visual>
    <collision>
      <origin
        xyz="0 0 0"
        rpy="0 0 0" />
      <geometry>
        <mesh
          filename="../meshes/base_linkv2.STL" />
      </geometry>
    </collision>
  </link>
  <link
    name="arm_leftv2">
    <contact>
        <lateral_friction value="0."/>
    </contact>
    <inertial>
      <origin
        xyz="6.4743188575433E-18 -0.00113539066808381 -0.00169513563308003"
        rpy="0 0 0" />
      <mass
        value="0.0024428" />
      <inertia
        ixx="1.3485795649656E-06"
        ixy="-9.63625619135692E-25"
        ixz="-6.56907102006461E-23"
        iyy="1.43243055204742E-06"
        iyz="-2.39392195336763E-08"
        izz="8.57927542515089E-08" />
    </inertial>
    <visual>
      <origin
        xyz="0 0 0"
        rpy="0 0 0" />
      <geometry>
        <mesh
          filename="../meshes/arm_leftv2.STL" />
      </geometry>
      <material
        name="">
        <color
          rgba="0.792156862745098 0.819607843137255 0.933333333333333 1" />
      </material>
    </visual>
    <collision>
      <origin
        xyz="0 0 0"
        rpy="0 0 0" />
      <geometry>
        <mesh
          filename="../meshes/arm_leftv2.STL" />
      </geometry>
    </collision>
  </link>
  <joint
    name="servo_leftv2"
    type="revolute">
    <origin
      xyz="0 0.0008 -0.04"
      rpy="0 0 0" />
    <parent
      link="base_linkv2" />
    <child
      link="arm_leftv2" />
    <axis
      xyz="-1 0 0" />
    <limit
      lower="0"
      upper="1.7"
      effort="0.01"
      velocity="6" />
  </joint>
  <link
    name="arm_rightv2">
    <contact>
        <lateral_friction value="0"/>
    </contact>
    <inertial>
      <origin
        xyz="-3.76466314275871E-17 -5.15811975585246E-05 0.00212340630696728"
        rpy="0 0 0" />
      <mass
        value="0.0024428" />
      <inertia
        ixx="1.3485795649656E-06"
        ixy="1.09407552500068E-24"
        ixz="-5.98109839421047E-23"
        iyy="1.43308255711055E-06"
        iyz="-1.13445872780218E-08"
        izz="8.51407491883854E-08" />
    </inertial>
    <visual>
      <origin
        xyz="0 0 0"
        rpy="0 0 0" />
      <geometry>
        <mesh
          filename="../meshes/arm_rightv2.STL" />
      </geometry>
      <material
        name="">
        <color
          rgba="0.792156862745098 0.819607843137255 0.933333333333333 1" />
      </material>
    </visual>
    <collision>
      <origin
        xyz="0 0 0"
        rpy="0 0 0" />
      <geometry>
        <mesh
          filename="../meshes/arm_rightv2.STL" />
      </geometry>
    </collision>
  </link>
  <joint
    name="servo_rightv2"
    type="revolute">
    <origin
      xyz="0 0.0008 0.04"
      rpy="0 0 0" />
    <parent
      link="base_linkv2" />
    <child
      link="arm_rightv2" />
    <axis
      xyz="-1 0 0" />
    <limit
      lower="0"
      upper="1.7"
      effort="0.01"
      velocity="6" />
  </joint>
</robot>