<?xml version="1.0" encoding="utf-8"?>
<!-- This URDF was automatically created by SolidWorks to URDF Exporter! Originally created by Stephen Brawner (brawner@gmail.com)
     Commit Version: 1.5.1-0-g916b5db  Build Version: 1.5.7152.31018
     For more information, please see http://wiki.ros.org/sw_urdf_exporter -->
<robot
  name="smarticle">
  <link
    name="base_link">
    <inertial>
      <origin
        xyz="0 2.157E-20 0.01515"
        rpy="0 0 0" />
      <mass
        value="0.033918" />
      <inertia
        ixx="1.0837E-05"
        ixy="-5.2677E-22"
        ixz="0"
        iyy="5.1389E-06"
        iyz="0"
        izz="1.0786E-05" />
    </inertial>
    <visual>
      <origin
        xyz="0 0 0"
        rpy="0 0 0" />
      <geometry>
        <mesh
          filename="../meshes/base_link_visual.STL" />
      </geometry>
      <material
        name="">
        <color
          rgba="0.29804 0.29804 0.29804 1" />
      </material>
    </visual>
    <collision>
      <origin
        xyz="0 0 0"
        rpy="0 0 0" />
      <geometry>
        <mesh
          filename="../meshes/base_link.STL" />
      </geometry>
    </collision>
  </link>
  <link
    name="arm_left">
    <inertial>
      <origin
        xyz="0.02234 3.4694E-18 0.01515"
        rpy="0 0 0" />
      <mass
        value="0.0039735" />
      <inertia
        ixx="4.928E-07"
        ixy="3.3351E-09"
        ixz="4.2578E-08"
        iyy="1.161E-06"
        iyz="-2.125E-10"
        izz="6.7795E-07" />
      </inertial>
    <visual>
      <origin
        xyz="0 0 0"
        rpy="0 0 0" />
      <geometry>
        <mesh
          filename="../meshes/arm_left_visual.STL" />
      </geometry>
      <material
        name="">
        <color
          rgba="0.25 0 0 1" />
      </material>
    </visual>
    <collision>
      <origin
        xyz="0 0 0"
        rpy="0 0 0" />
      <geometry>
        <mesh
          filename="../meshes/arm_left_visual.STL" />
      </geometry>
    </collision>
  </link>
  <joint
    name="servo_left"
    type="revolute">
    <origin
      xyz="-0.0015 0.0212 0.001"
      rpy="0 0 0.2635" />
    <parent
      link="base_link" />
    <child
      link="arm_left" />
    <axis
      xyz="0 0 -1" />
    <limit
      lower="-1.8"
      upper="1.8"
      effort="0.028"
      velocity="6.8" />
  </joint>
  <link
    name="arm_right">
    <inertial>
      <origin
        xyz="0.02234 8.6736E-19 0.01515"
        rpy="0 0 0" />
      <mass
        value="0.0039735" />
      <inertia
        ixx="4.928E-07"
        ixy="3.3351E-09"
        ixz="4.2578E-08"
        iyy="1.161E-06"
        iyz="-2.125E-10"
        izz="6.7795E-07" />
    </inertial>
    <visual>
      <origin
        xyz="0 0 0"
        rpy="0 0 0" />
      <geometry>
        <mesh
          filename="../meshes/arm_right_visual.STL" />
      </geometry>
      <material
        name="">
        <color
          rgba="0 0 1 1" />
      </material>
    </visual>
    <collision>
      <origin
        xyz="0 0 0"
        rpy="0 0 0" />
      <geometry>
        <mesh
          filename="../meshes/arm_right.STL" />
      </geometry>
    </collision>
  </link>
  <joint
    name="servo_right"
    type="revolute">
    <origin
      xyz="-0.0015 -0.0212 0.001"
      rpy="0 0 -1.4465" />
    <parent
      link="base_link" />
    <child
      link="arm_right" />
    <axis
      xyz="0 0 -1" />
    <limit
      lower="-1.8"
      upper="1.8"
      effort="0.028"
      velocity="6.8" />
  </joint>
</robot>
