<?xml version="1.0" encoding="utf-8"?>
<!-- This URDF was automatically created by SolidWorks to URDF Exporter! Originally created by Stephen Brawner (brawner@gmail.com) 
     Commit Version: 1.5.1-0-g916b5db  Build Version: 1.5.7152.31018
     For more information, please see http://wiki.ros.org/sw_urdf_exporter -->
<robot
  name="simulation_assembly">
  <link
    name="base_link">
    <inertial>
      <origin
        xyz="0 0 0.01515"
        rpy="0 0 0" />
      <mass
        value="0.033918" />
      <inertia
        ixx="1.0837E-05"
        ixy="0"
        ixz="0"
        iyy="5.1389E-06"
        iyz="0"
        izz="1.0786E-05" />
    </inertial>
    <visual>
      <origin
        xyz="0 0 0"
        rpy="0 0 0" />
      <geometry>
        <mesh
          filename="package://simulation_assembly/meshes/base_link.STL" />
      </geometry>
      <material
        name="">
        <color
          rgba="0.29804 0.29804 0.29804 1" />
      </material>
    </visual>
    <collision>
      <origin
        xyz="0 0 0"
        rpy="0 0 0" />
      <geometry>
        <mesh
          filename="package://simulation_assembly/meshes/base_link.STL" />
      </geometry>
    </collision>
  </link>
  <link
    name="arm_left">
    <inertial>
      <origin
        xyz="0.02234 0 0.01515"
        rpy="0 0 0" />
      <mass
        value="0.0039735" />
      <inertia
        ixx="0.0005233"
        ixy="0"
        ixz="-5.7973E-23"
        iyy="1.2406E-06"
        iyz="-1.906E-24"
        izz="9.3957E-07" />
    </inertial>
    <visual>
      <origin
        xyz="0 0 0"
        rpy="0 0 0" />
      <geometry>
        <mesh
          filename="package://simulation_assembly/meshes/arm_left.STL" />
      </geometry>
      <material
        name="">
        <color
          rgba="0.29804 0.29804 0.29804 1" />
      </material>
    </visual>
    <collision>
      <origin
        xyz="0 0 0"
        rpy="0 0 0" />
      <geometry>
        <mesh
          filename="package://simulation_assembly/meshes/arm_left.STL" />
      </geometry>
    </collision>
  </link>
  <joint
    name="servo_left"
    type="continuous">
    <origin
      xyz="-0.0015 0.0212 0.001"
      rpy="0 0 0" />
    <parent
      link="base_link" />
    <child
      link="arm_left" />
    <axis
      xyz="0 0 1" />
  </joint>
  <link
    name="arm_right">
    <inertial>
      <origin
        xyz="0.02234 0 0.01515"
        rpy="0 0 0" />
      <mass
        value="0.0039735" />
      <inertia
        ixx="3.0696E-07"
        ixy="3.9705E-23"
        ixz="1.688E-22"
        iyy="1.2406E-06"
        iyz="1.6997E-23"
        izz="9.3957E-07" />
    </inertial>
    <visual>
      <origin
        xyz="0 0 0"
        rpy="0 0 0" />
      <geometry>
        <mesh
          filename="package://simulation_assembly/meshes/arm_right.STL" />
      </geometry>
      <material
        name="">
        <color
          rgba="0.29804 0.29804 0.29804 1" />
      </material>
    </visual>
    <collision>
      <origin
        xyz="0 0 0"
        rpy="0 0 0" />
      <geometry>
        <mesh
          filename="package://simulation_assembly/meshes/arm_right.STL" />
      </geometry>
    </collision>
  </link>
  <joint
    name="servo_rigth"
    type="revolute">
    <origin
      xyz="-0.0015 -0.0212 0.001"
      rpy="0 0 0" />
    <parent
      link="base_link" />
    <child
      link="arm_right" />
    <axis
      xyz="0 0 1" />
    <limit
      lower="-1.8"
      upper="1.8"
      effort="0.03"
      velocity="6" />
  </joint>
</robot>